data/sample_orders.csv
timestamp,action,order_id,side,type,price,quantity
1,ADD,1001,BUY,LIMIT,10050,200
2,ADD,1002,SELL,LIMIT,10070,100
3,ADD,1003,SELL,LIMIT,10060,120
4,ADD,1004,BUY,LIMIT,10065,150
5,CANCEL,1001,BUY,LIMIT,10050,200
6,ADD,1005,SELL,MARKET,0,20
7,ADD,1006,BUY,MARKET,0,70
8,ADD,1007,BUY,LIMIT,10055,40
